2025-08-15 18:05:58,416 - ERROR - Ошибка в обработчике команд /start для пользователя 1050315821: type object 'Form' has no attribute 'waiting_for_type'
2025-08-15 18:06:32,880 - ERROR - Ошибка в обработчике команд /start для пользователя 1050315821: type object 'Form' has no attribute 'waiting_for_type'
2025-08-15 18:07:00,561 - ERROR - Ошибка в обработчике команд /start для пользователя 1050315821: type object 'Form' has no attribute 'waiting_for_type'
2025-08-18 11:52:20,404 - ERROR - Ошибка в обработчике команд /start для пользователя 896220662: type object 'Form' has no attribute 'waiting_for_type'
2025-08-20 13:59:22,046 - ERROR - Ошибка в обработчике команд /start для пользователя 1050315821: type object 'Form' has no attribute 'waiting_for_type'
2025-08-20 14:01:52,173 - ERROR - Ошибка в обработчике команд /start для пользователя 1050315821: type object 'Form' has no attribute 'waiting_for_type'
2025-08-20 14:03:19,533 - ERROR - Ошибка в обработчике команд /start для пользователя 7539844857: type object 'Form' has no attribute 'waiting_for_type'
2025-08-20 14:12:55,302 - ERROR - Ошибка в обработчике команд /start для пользователя 7539844857: type object 'Form' has no attribute 'waiting_for_type'
2025-08-20 14:16:35,437 - ERROR - Ошибка в обработчике команд /start для пользователя 7539844857: type object 'Form' has no attribute 'waiting_for_type'
2025-08-20 14:21:39,070 - ERROR - Ошибка в обработчике команд /start для пользователя 7539844857: type object 'Form' has no attribute 'waiting_for_type'
2025-08-20 14:26:05,143 - ERROR - Ошибка в обработчике команд /start для пользователя 7539844857: type object 'Form' has no attribute 'waiting_for_type'
2025-08-20 14:28:36,905 - ERROR - Ошибка в обработчике команд /start для пользователя 7539844857: type object 'Form' has no attribute 'waiting_for_type'
2025-08-20 14:31:05,601 - ERROR - Ошибка в обработчике команд /start для пользователя 7539844857: type object 'Form' has no attribute 'waiting_for_type'
2025-08-20 14:47:20,321 - ERROR - Ошибка в обработчике команд /start для пользователя 7539844857: type object 'Form' has no attribute 'waiting_for_type'
Traceback (most recent call last):
  File "C:\education\education\tgbotpsy\bot\main.py", line 34, in cmd_start
    await state.set_state(Form.waiting_for_type)
                          ^^^^^^^^^^^^^^^^^^^^^
AttributeError: type object 'Form' has no attribute 'waiting_for_type'
2025-08-20 14:57:06,067 - ERROR - Ошибка в обработчике команд /start для пользователя 7539844857: type object 'Form' has no attribute 'waiting_for_type'
Traceback (most recent call last):
  File "C:\education\education\tgbotpsy\bot\main.py", line 34, in cmd_start
    await state.set_state(Form.waiting_for_type)
                          ^^^^^^^^^^^^^^^^^^^^^
AttributeError: type object 'Form' has no attribute 'waiting_for_type'
2025-08-20 15:03:15,525 - ERROR - Ошибка в обработчике команд /start для пользователя 7539844857: type object 'Form' has no attribute 'waiting_for_type'
Traceback (most recent call last):
  File "C:\education\education\tgbotpsy\bot\main.py", line 34, in cmd_start
    await state.set_state(Form.waiting_for_type)
                          ^^^^^^^^^^^^^^^^^^^^^
AttributeError: type object 'Form' has no attribute 'waiting_for_type'
2025-08-20 15:10:06,011 - ERROR - Ошибка в обработчике команд /start для пользователя 7539844857: type object 'Form' has no attribute 'waiting_for_type'
Traceback (most recent call last):
  File "C:\education\education\tgbotpsy\bot\main.py", line 34, in cmd_start
    await state.set_state(Form.waiting_for_type)
                          ^^^^^^^^^^^^^^^^^^^^^
AttributeError: type object 'Form' has no attribute 'waiting_for_type'
2025-08-20 15:12:21,968 - ERROR - Ошибка в обработчике команд /start для пользователя 7539844857: type object 'Form' has no attribute 'waiting_for_type'
Traceback (most recent call last):
  File "C:\education\education\tgbotpsy\bot\main.py", line 34, in cmd_start
    await state.set_state(Form.waiting_for_type)
                          ^^^^^^^^^^^^^^^^^^^^^
AttributeError: type object 'Form' has no attribute 'waiting_for_type'
2025-08-20 15:22:42,152 - ERROR - Исключение в main(): Router.include_router() got an unexpected keyword argument 'storage'
Traceback (most recent call last):
  File "C:\education\education\tgbotpsy\bot\main.py", line 21, in main
    dp.include_router(question.router, storage=storage)
    ~~~~~~~~~~~~~~~~~^^^^^^^^^^^^^^^^^^^^^^^^^^^^^^^^^^
TypeError: Router.include_router() got an unexpected keyword argument 'storage'
2025-08-20 15:23:00,704 - ERROR - Исключение в main(): Router.include_router() got an unexpected keyword argument 'storage'
Traceback (most recent call last):
  File "C:\education\education\tgbotpsy\bot\main.py", line 21, in main
    dp.include_router(question.router, storage=storage)
    ~~~~~~~~~~~~~~~~~^^^^^^^^^^^^^^^^^^^^^^^^^^^^^^^^^^
TypeError: Router.include_router() got an unexpected keyword argument 'storage'
2025-08-20 15:30:43,151 - ERROR - Исключение в main(): At least one bot instance is required to start polling
Traceback (most recent call last):
  File "C:\education\education\tgbotpsy\bot\main.py", line 39, in main
    await dp.start_polling()
  File "C:\education\education\tgbotpsy\.venv\Lib\site-packages\aiogram\dispatcher\dispatcher.py", line 525, in start_polling
    raise ValueError("At least one bot instance is required to start polling")
ValueError: At least one bot instance is required to start polling
2025-08-20 15:33:13,531 - ERROR - Ошибка в обработчике команд /start для пользователя 7539844857: type object 'Form' has no attribute 'waiting_for_type'
Traceback (most recent call last):
  File "C:\education\education\tgbotpsy\bot\main.py", line 31, in cmd_start
    await state.set_state(Form.waiting_for_type)
                          ^^^^^^^^^^^^^^^^^^^^^
AttributeError: type object 'Form' has no attribute 'waiting_for_type'
2025-08-20 16:01:10,410 - ERROR - Ошибка в обработчике команд /start для пользователя 1050315821: type object 'Form' has no attribute 'waiting_for_type'
Traceback (most recent call last):
  File "C:\education\education\tgbotpsy\bot\main.py", line 32, in cmd_start
    await state.set_state(Form.waiting_for_type)
                          ^^^^^^^^^^^^^^^^^^^^^
AttributeError: type object 'Form' has no attribute 'waiting_for_type'
2025-08-20 16:04:56,417 - ERROR - Ошибка в обработчике команд /start для пользователя 1050315821: type object 'Form' has no attribute 'waiting_for_type'
Traceback (most recent call last):
  File "C:\education\education\tgbotpsy\bot\main.py", line 32, in cmd_start
    await state.set_state(Form.waiting_for_type)
                          ^^^^^^^^^^^^^^^^^^^^^
AttributeError: type object 'Form' has no attribute 'waiting_for_type'
2025-09-17 12:08:28,029 - ERROR - Ошибка в personal_data_agreement для пользователя 1050315821: 2 validation errors for SendMessage
chat_id.int
  Input should be a valid integer [type=int_type, input_value=[1050315821, 8490448672], input_type=list]
    For further information visit https://errors.pydantic.dev/2.11/v/int_type
chat_id.str
  Input should be a valid string [type=string_type, input_value=[1050315821, 8490448672], input_type=list]
    For further information visit https://errors.pydantic.dev/2.11/v/string_type
Traceback (most recent call last):
  File "C:\education\education\tgbotpsy\bot\handlers\free_consult.py", line 242, in personal_data_agreement
    await notify_admin_about_application(message.bot, app)
  File "C:\education\education\tgbotpsy\bot\handlers\free_consult.py", line 80, in notify_admin_about_application
    await bot.send_message(chat_id=ADMIN_CHAT_IDS, text=text, reply_markup=markup)
  File "C:\education\education\tgbotpsy\.venv\Lib\site-packages\aiogram\client\bot.py", line 2836, in send_message
    call = SendMessage(
        chat_id=chat_id,
    ...<14 lines>...
        reply_to_message_id=reply_to_message_id,
    )
  File "C:\education\education\tgbotpsy\.venv\Lib\site-packages\pydantic\main.py", line 253, in __init__
    validated_self = self.__pydantic_validator__.validate_python(data, self_instance=self)
pydantic_core._pydantic_core.ValidationError: 2 validation errors for SendMessage
chat_id.int
  Input should be a valid integer [type=int_type, input_value=[1050315821, 8490448672], input_type=list]
    For further information visit https://errors.pydantic.dev/2.11/v/int_type
chat_id.str
  Input should be a valid string [type=string_type, input_value=[1050315821, 8490448672], input_type=list]
    For further information visit https://errors.pydantic.dev/2.11/v/string_type
2025-09-17 12:11:19,364 - ERROR - Ошибка в personal_data_agreement для пользователя 1050315821: 2 validation errors for SendMessage
chat_id.int
  Input should be a valid integer [type=int_type, input_value=[1050315821, 8490448672], input_type=list]
    For further information visit https://errors.pydantic.dev/2.11/v/int_type
chat_id.str
  Input should be a valid string [type=string_type, input_value=[1050315821, 8490448672], input_type=list]
    For further information visit https://errors.pydantic.dev/2.11/v/string_type
Traceback (most recent call last):
  File "C:\education\education\tgbotpsy\bot\handlers\free_consult.py", line 242, in personal_data_agreement
    await notify_admin_about_application(message.bot, app)
  File "C:\education\education\tgbotpsy\bot\handlers\free_consult.py", line 80, in notify_admin_about_application
    await bot.send_message(chat_id=ADMIN_CHAT_IDS, text=text, reply_markup=markup)
  File "C:\education\education\tgbotpsy\.venv\Lib\site-packages\aiogram\client\bot.py", line 2836, in send_message
    call = SendMessage(
        chat_id=chat_id,
    ...<14 lines>...
        reply_to_message_id=reply_to_message_id,
    )
  File "C:\education\education\tgbotpsy\.venv\Lib\site-packages\pydantic\main.py", line 253, in __init__
    validated_self = self.__pydantic_validator__.validate_python(data, self_instance=self)
pydantic_core._pydantic_core.ValidationError: 2 validation errors for SendMessage
chat_id.int
  Input should be a valid integer [type=int_type, input_value=[1050315821, 8490448672], input_type=list]
    For further information visit https://errors.pydantic.dev/2.11/v/int_type
chat_id.str
  Input should be a valid string [type=string_type, input_value=[1050315821, 8490448672], input_type=list]
    For further information visit https://errors.pydantic.dev/2.11/v/string_type
2025-09-17 12:45:01,101 - ERROR - Ошибка в personal_data_agreement для пользователя 1050315821: 2 validation errors for SendMessage
chat_id.int
  Input should be a valid integer [type=int_type, input_value=[1050315821, 8490448672], input_type=list]
    For further information visit https://errors.pydantic.dev/2.11/v/int_type
chat_id.str
  Input should be a valid string [type=string_type, input_value=[1050315821, 8490448672], input_type=list]
    For further information visit https://errors.pydantic.dev/2.11/v/string_type
Traceback (most recent call last):
  File "C:\education\education\tgbotpsy\bot\handlers\paid_consult.py", line 212, in personal_data_agreement
    await notify_admin_about_application(message.bot, app)
  File "C:\education\education\tgbotpsy\bot\handlers\paid_consult.py", line 66, in notify_admin_about_application
    await bot.send_message(chat_id=ADMIN_CHAT_IDS, text=text, reply_markup=markup)
  File "C:\education\education\tgbotpsy\.venv\Lib\site-packages\aiogram\client\bot.py", line 2836, in send_message
    call = SendMessage(
        chat_id=chat_id,
    ...<14 lines>...
        reply_to_message_id=reply_to_message_id,
    )
  File "C:\education\education\tgbotpsy\.venv\Lib\site-packages\pydantic\main.py", line 253, in __init__
    validated_self = self.__pydantic_validator__.validate_python(data, self_instance=self)
pydantic_core._pydantic_core.ValidationError: 2 validation errors for SendMessage
chat_id.int
  Input should be a valid integer [type=int_type, input_value=[1050315821, 8490448672], input_type=list]
    For further information visit https://errors.pydantic.dev/2.11/v/int_type
chat_id.str
  Input should be a valid string [type=string_type, input_value=[1050315821, 8490448672], input_type=list]
    For further information visit https://errors.pydantic.dev/2.11/v/string_type
